2021-03-18 12:37:14,277 [INFO   ] [APP] autotrader started with arguments={-c}
2021-03-18 12:37:14,277 [INFO   ] [APP] configuration={"Execution":{"Host":"192.168.77.11","Port":12345},"Information":{"Interface":"0.0.0.0","ListenAddress":"192.168.77.255","Port":12346},"TeamName":"Substandard_and_Poor","Secret":"481709ea92aa4a4fb3d525fa5edd60d9"}
2021-03-18 12:37:14,279 [INFO   ] [CONNECTION] fd=8 connection established: peer=192.168.77.11:12345
2021-03-18 12:37:34,685 [ERROR  ] [asyncio] Exception in callback _SelectorDatagramTransport._read_ready()
handle: <Handle _SelectorDatagramTransport._read_ready()>
Traceback (most recent call last):
  File "/usr/local/lib/python3.6/asyncio/events.py", line 145, in _run
    self._callback(*self._args)
  File "/usr/local/lib/python3.6/asyncio/selector_events.py", line 1068, in _read_ready
    self._protocol.datagram_received(data, addr)
  File "/trader_one/ready_trader_one/messages.py", line 194, in datagram_received
    self.on_datagram(typ, data, HEADER_SIZE, length)
  File "/trader_one/ready_trader_one/base_auto_trader.py", line 63, in on_datagram
    self.on_order_book_update_message(inst, seq, *BOOK_PART.iter_unpack(data[ORDER_BOOK_HEADER_SIZE:]))
  File "/trader_one/autotrader.py", line 92, in on_order_book_update_message
    self.send_insert_order(self.bids[0], Side.BUY, new_bid_price, new_bid_volume, Lifespan.GOOD_FOR_DAY)
  File "/trader_one/ready_trader_one/base_auto_trader.py", line 150, in send_insert_order
    INSERT_MESSAGE.pack(client_order_id, side, price, volume, lifespan),
struct.error: argument out of range
2021-03-18 12:37:34,934 [ERROR  ] [asyncio] Exception in callback _SelectorDatagramTransport._read_ready()
handle: <Handle _SelectorDatagramTransport._read_ready()>
Traceback (most recent call last):
  File "/usr/local/lib/python3.6/asyncio/events.py", line 145, in _run
    self._callback(*self._args)
  File "/usr/local/lib/python3.6/asyncio/selector_events.py", line 1068, in _read_ready
    self._protocol.datagram_received(data, addr)
  File "/trader_one/ready_trader_one/messages.py", line 194, in datagram_received
    self.on_datagram(typ, data, HEADER_SIZE, length)
  File "/trader_one/ready_trader_one/base_auto_trader.py", line 63, in on_datagram
    self.on_order_book_update_message(inst, seq, *BOOK_PART.iter_unpack(data[ORDER_BOOK_HEADER_SIZE:]))
  File "/trader_one/autotrader.py", line 92, in on_order_book_update_message
    self.send_insert_order(self.bids[0], Side.BUY, new_bid_price, new_bid_volume, Lifespan.GOOD_FOR_DAY)
  File "/trader_one/ready_trader_one/base_auto_trader.py", line 150, in send_insert_order
    INSERT_MESSAGE.pack(client_order_id, side, price, volume, lifespan),
struct.error: argument out of range
2021-03-18 12:37:34,938 [WARNING] [TRADER] error with order 23: out-of-order client_order_id in cancel message
2021-03-18 12:37:35,184 [ERROR  ] [asyncio] Exception in callback _SelectorDatagramTransport._read_ready()
handle: <Handle _SelectorDatagramTransport._read_ready()>
Traceback (most recent call last):
  File "/usr/local/lib/python3.6/asyncio/events.py", line 145, in _run
    self._callback(*self._args)
  File "/usr/local/lib/python3.6/asyncio/selector_events.py", line 1068, in _read_ready
    self._protocol.datagram_received(data, addr)
  File "/trader_one/ready_trader_one/messages.py", line 194, in datagram_received
    self.on_datagram(typ, data, HEADER_SIZE, length)
  File "/trader_one/ready_trader_one/base_auto_trader.py", line 63, in on_datagram
    self.on_order_book_update_message(inst, seq, *BOOK_PART.iter_unpack(data[ORDER_BOOK_HEADER_SIZE:]))
  File "/trader_one/autotrader.py", line 100, in on_order_book_update_message
    Lifespan.GOOD_FOR_DAY)
  File "/trader_one/ready_trader_one/base_auto_trader.py", line 150, in send_insert_order
    INSERT_MESSAGE.pack(client_order_id, side, price, volume, lifespan),
struct.error: argument out of range
2021-03-18 12:37:36,937 [ERROR  ] [asyncio] Exception in callback _SelectorDatagramTransport._read_ready()
handle: <Handle _SelectorDatagramTransport._read_ready()>
Traceback (most recent call last):
  File "/usr/local/lib/python3.6/asyncio/events.py", line 145, in _run
    self._callback(*self._args)
  File "/usr/local/lib/python3.6/asyncio/selector_events.py", line 1068, in _read_ready
    self._protocol.datagram_received(data, addr)
  File "/trader_one/ready_trader_one/messages.py", line 194, in datagram_received
    self.on_datagram(typ, data, HEADER_SIZE, length)
  File "/trader_one/ready_trader_one/base_auto_trader.py", line 63, in on_datagram
    self.on_order_book_update_message(inst, seq, *BOOK_PART.iter_unpack(data[ORDER_BOOK_HEADER_SIZE:]))
  File "/trader_one/autotrader.py", line 100, in on_order_book_update_message
    Lifespan.GOOD_FOR_DAY)
  File "/trader_one/ready_trader_one/base_auto_trader.py", line 150, in send_insert_order
    INSERT_MESSAGE.pack(client_order_id, side, price, volume, lifespan),
struct.error: argument out of range
2021-03-18 12:37:37,437 [ERROR  ] [asyncio] Exception in callback _SelectorDatagramTransport._read_ready()
handle: <Handle _SelectorDatagramTransport._read_ready()>
Traceback (most recent call last):
  File "/usr/local/lib/python3.6/asyncio/events.py", line 145, in _run
    self._callback(*self._args)
  File "/usr/local/lib/python3.6/asyncio/selector_events.py", line 1068, in _read_ready
    self._protocol.datagram_received(data, addr)
  File "/trader_one/ready_trader_one/messages.py", line 194, in datagram_received
    self.on_datagram(typ, data, HEADER_SIZE, length)
  File "/trader_one/ready_trader_one/base_auto_trader.py", line 63, in on_datagram
    self.on_order_book_update_message(inst, seq, *BOOK_PART.iter_unpack(data[ORDER_BOOK_HEADER_SIZE:]))
  File "/trader_one/autotrader.py", line 100, in on_order_book_update_message
    Lifespan.GOOD_FOR_DAY)
  File "/trader_one/ready_trader_one/base_auto_trader.py", line 150, in send_insert_order
    INSERT_MESSAGE.pack(client_order_id, side, price, volume, lifespan),
struct.error: argument out of range
2021-03-18 12:37:37,685 [ERROR  ] [asyncio] Exception in callback _SelectorDatagramTransport._read_ready()
handle: <Handle _SelectorDatagramTransport._read_ready()>
Traceback (most recent call last):
  File "/usr/local/lib/python3.6/asyncio/events.py", line 145, in _run
    self._callback(*self._args)
  File "/usr/local/lib/python3.6/asyncio/selector_events.py", line 1068, in _read_ready
    self._protocol.datagram_received(data, addr)
  File "/trader_one/ready_trader_one/messages.py", line 194, in datagram_received
    self.on_datagram(typ, data, HEADER_SIZE, length)
  File "/trader_one/ready_trader_one/base_auto_trader.py", line 63, in on_datagram
    self.on_order_book_update_message(inst, seq, *BOOK_PART.iter_unpack(data[ORDER_BOOK_HEADER_SIZE:]))
  File "/trader_one/autotrader.py", line 100, in on_order_book_update_message
    Lifespan.GOOD_FOR_DAY)
  File "/trader_one/ready_trader_one/base_auto_trader.py", line 150, in send_insert_order
    INSERT_MESSAGE.pack(client_order_id, side, price, volume, lifespan),
struct.error: argument out of range
2021-03-18 13:35:33,684 [ERROR  ] [asyncio] Exception in callback _SelectorDatagramTransport._read_ready()
handle: <Handle _SelectorDatagramTransport._read_ready()>
Traceback (most recent call last):
  File "/usr/local/lib/python3.6/asyncio/events.py", line 145, in _run
    self._callback(*self._args)
  File "/usr/local/lib/python3.6/asyncio/selector_events.py", line 1068, in _read_ready
    self._protocol.datagram_received(data, addr)
  File "/trader_one/ready_trader_one/messages.py", line 194, in datagram_received
    self.on_datagram(typ, data, HEADER_SIZE, length)
  File "/trader_one/ready_trader_one/base_auto_trader.py", line 63, in on_datagram
    self.on_order_book_update_message(inst, seq, *BOOK_PART.iter_unpack(data[ORDER_BOOK_HEADER_SIZE:]))
  File "/trader_one/autotrader.py", line 92, in on_order_book_update_message
    self.send_insert_order(self.bids[0], Side.BUY, new_bid_price, new_bid_volume, Lifespan.GOOD_FOR_DAY)
  File "/trader_one/ready_trader_one/base_auto_trader.py", line 150, in send_insert_order
    INSERT_MESSAGE.pack(client_order_id, side, price, volume, lifespan),
struct.error: argument out of range
2021-03-18 13:35:35,683 [ERROR  ] [asyncio] Exception in callback _SelectorDatagramTransport._read_ready()
handle: <Handle _SelectorDatagramTransport._read_ready()>
Traceback (most recent call last):
  File "/usr/local/lib/python3.6/asyncio/events.py", line 145, in _run
    self._callback(*self._args)
  File "/usr/local/lib/python3.6/asyncio/selector_events.py", line 1068, in _read_ready
    self._protocol.datagram_received(data, addr)
  File "/trader_one/ready_trader_one/messages.py", line 194, in datagram_received
    self.on_datagram(typ, data, HEADER_SIZE, length)
  File "/trader_one/ready_trader_one/base_auto_trader.py", line 63, in on_datagram
    self.on_order_book_update_message(inst, seq, *BOOK_PART.iter_unpack(data[ORDER_BOOK_HEADER_SIZE:]))
  File "/trader_one/autotrader.py", line 100, in on_order_book_update_message
    Lifespan.GOOD_FOR_DAY)
  File "/trader_one/ready_trader_one/base_auto_trader.py", line 150, in send_insert_order
    INSERT_MESSAGE.pack(client_order_id, side, price, volume, lifespan),
struct.error: argument out of range
2021-03-18 13:35:35,683 [WARNING] [TRADER] error with order 114: out-of-order client_order_id in cancel message
2021-03-18 13:35:36,684 [ERROR  ] [asyncio] Exception in callback _SelectorDatagramTransport._read_ready()
handle: <Handle _SelectorDatagramTransport._read_ready()>
Traceback (most recent call last):
  File "/usr/local/lib/python3.6/asyncio/events.py", line 145, in _run
    self._callback(*self._args)
  File "/usr/local/lib/python3.6/asyncio/selector_events.py", line 1068, in _read_ready
    self._protocol.datagram_received(data, addr)
  File "/trader_one/ready_trader_one/messages.py", line 194, in datagram_received
    self.on_datagram(typ, data, HEADER_SIZE, length)
  File "/trader_one/ready_trader_one/base_auto_trader.py", line 63, in on_datagram
    self.on_order_book_update_message(inst, seq, *BOOK_PART.iter_unpack(data[ORDER_BOOK_HEADER_SIZE:]))
  File "/trader_one/autotrader.py", line 92, in on_order_book_update_message
    self.send_insert_order(self.bids[0], Side.BUY, new_bid_price, new_bid_volume, Lifespan.GOOD_FOR_DAY)
  File "/trader_one/ready_trader_one/base_auto_trader.py", line 150, in send_insert_order
    INSERT_MESSAGE.pack(client_order_id, side, price, volume, lifespan),
struct.error: argument out of range
2021-03-18 13:35:36,685 [WARNING] [TRADER] error with order 115: out-of-order client_order_id in cancel message
2021-03-18 13:35:40,683 [ERROR  ] [asyncio] Exception in callback _SelectorDatagramTransport._read_ready()
handle: <Handle _SelectorDatagramTransport._read_ready()>
Traceback (most recent call last):
  File "/usr/local/lib/python3.6/asyncio/events.py", line 145, in _run
    self._callback(*self._args)
  File "/usr/local/lib/python3.6/asyncio/selector_events.py", line 1068, in _read_ready
    self._protocol.datagram_received(data, addr)
  File "/trader_one/ready_trader_one/messages.py", line 194, in datagram_received
    self.on_datagram(typ, data, HEADER_SIZE, length)
  File "/trader_one/ready_trader_one/base_auto_trader.py", line 63, in on_datagram
    self.on_order_book_update_message(inst, seq, *BOOK_PART.iter_unpack(data[ORDER_BOOK_HEADER_SIZE:]))
  File "/trader_one/autotrader.py", line 100, in on_order_book_update_message
    Lifespan.GOOD_FOR_DAY)
  File "/trader_one/ready_trader_one/base_auto_trader.py", line 150, in send_insert_order
    INSERT_MESSAGE.pack(client_order_id, side, price, volume, lifespan),
struct.error: argument out of range
2021-03-18 13:35:40,685 [WARNING] [TRADER] error with order 116: out-of-order client_order_id in cancel message
2021-03-18 13:35:43,683 [ERROR  ] [asyncio] Exception in callback _SelectorDatagramTransport._read_ready()
handle: <Handle _SelectorDatagramTransport._read_ready()>
Traceback (most recent call last):
  File "/usr/local/lib/python3.6/asyncio/events.py", line 145, in _run
    self._callback(*self._args)
  File "/usr/local/lib/python3.6/asyncio/selector_events.py", line 1068, in _read_ready
    self._protocol.datagram_received(data, addr)
  File "/trader_one/ready_trader_one/messages.py", line 194, in datagram_received
    self.on_datagram(typ, data, HEADER_SIZE, length)
  File "/trader_one/ready_trader_one/base_auto_trader.py", line 63, in on_datagram
    self.on_order_book_update_message(inst, seq, *BOOK_PART.iter_unpack(data[ORDER_BOOK_HEADER_SIZE:]))
  File "/trader_one/autotrader.py", line 92, in on_order_book_update_message
    self.send_insert_order(self.bids[0], Side.BUY, new_bid_price, new_bid_volume, Lifespan.GOOD_FOR_DAY)
  File "/trader_one/ready_trader_one/base_auto_trader.py", line 150, in send_insert_order
    INSERT_MESSAGE.pack(client_order_id, side, price, volume, lifespan),
struct.error: argument out of range
2021-03-18 13:35:43,684 [WARNING] [TRADER] error with order 117: out-of-order client_order_id in cancel message
2021-03-18 13:35:47,184 [ERROR  ] [asyncio] Exception in callback _SelectorDatagramTransport._read_ready()
handle: <Handle _SelectorDatagramTransport._read_ready()>
Traceback (most recent call last):
  File "/usr/local/lib/python3.6/asyncio/events.py", line 145, in _run
    self._callback(*self._args)
  File "/usr/local/lib/python3.6/asyncio/selector_events.py", line 1068, in _read_ready
    self._protocol.datagram_received(data, addr)
  File "/trader_one/ready_trader_one/messages.py", line 194, in datagram_received
    self.on_datagram(typ, data, HEADER_SIZE, length)
  File "/trader_one/ready_trader_one/base_auto_trader.py", line 63, in on_datagram
    self.on_order_book_update_message(inst, seq, *BOOK_PART.iter_unpack(data[ORDER_BOOK_HEADER_SIZE:]))
  File "/trader_one/autotrader.py", line 92, in on_order_book_update_message
    self.send_insert_order(self.bids[0], Side.BUY, new_bid_price, new_bid_volume, Lifespan.GOOD_FOR_DAY)
  File "/trader_one/ready_trader_one/base_auto_trader.py", line 150, in send_insert_order
    INSERT_MESSAGE.pack(client_order_id, side, price, volume, lifespan),
struct.error: argument out of range
2021-03-18 13:35:48,184 [ERROR  ] [asyncio] Exception in callback _SelectorDatagramTransport._read_ready()
handle: <Handle _SelectorDatagramTransport._read_ready()>
Traceback (most recent call last):
  File "/usr/local/lib/python3.6/asyncio/events.py", line 145, in _run
    self._callback(*self._args)
  File "/usr/local/lib/python3.6/asyncio/selector_events.py", line 1068, in _read_ready
    self._protocol.datagram_received(data, addr)
  File "/trader_one/ready_trader_one/messages.py", line 194, in datagram_received
    self.on_datagram(typ, data, HEADER_SIZE, length)
  File "/trader_one/ready_trader_one/base_auto_trader.py", line 63, in on_datagram
    self.on_order_book_update_message(inst, seq, *BOOK_PART.iter_unpack(data[ORDER_BOOK_HEADER_SIZE:]))
  File "/trader_one/autotrader.py", line 92, in on_order_book_update_message
    self.send_insert_order(self.bids[0], Side.BUY, new_bid_price, new_bid_volume, Lifespan.GOOD_FOR_DAY)
  File "/trader_one/ready_trader_one/base_auto_trader.py", line 150, in send_insert_order
    INSERT_MESSAGE.pack(client_order_id, side, price, volume, lifespan),
struct.error: argument out of range
2021-03-18 13:35:48,185 [WARNING] [TRADER] error with order 118: out-of-order client_order_id in cancel message
2021-03-18 13:35:48,683 [ERROR  ] [asyncio] Exception in callback _SelectorDatagramTransport._read_ready()
handle: <Handle _SelectorDatagramTransport._read_ready()>
Traceback (most recent call last):
  File "/usr/local/lib/python3.6/asyncio/events.py", line 145, in _run
    self._callback(*self._args)
  File "/usr/local/lib/python3.6/asyncio/selector_events.py", line 1068, in _read_ready
    self._protocol.datagram_received(data, addr)
  File "/trader_one/ready_trader_one/messages.py", line 194, in datagram_received
    self.on_datagram(typ, data, HEADER_SIZE, length)
  File "/trader_one/ready_trader_one/base_auto_trader.py", line 63, in on_datagram
    self.on_order_book_update_message(inst, seq, *BOOK_PART.iter_unpack(data[ORDER_BOOK_HEADER_SIZE:]))
  File "/trader_one/autotrader.py", line 92, in on_order_book_update_message
    self.send_insert_order(self.bids[0], Side.BUY, new_bid_price, new_bid_volume, Lifespan.GOOD_FOR_DAY)
  File "/trader_one/ready_trader_one/base_auto_trader.py", line 150, in send_insert_order
    INSERT_MESSAGE.pack(client_order_id, side, price, volume, lifespan),
struct.error: argument out of range
2021-03-18 13:35:48,685 [WARNING] [TRADER] error with order 119: out-of-order client_order_id in cancel message
2021-03-18 13:35:52,183 [ERROR  ] [asyncio] Exception in callback _SelectorDatagramTransport._read_ready()
handle: <Handle _SelectorDatagramTransport._read_ready()>
Traceback (most recent call last):
  File "/usr/local/lib/python3.6/asyncio/events.py", line 145, in _run
    self._callback(*self._args)
  File "/usr/local/lib/python3.6/asyncio/selector_events.py", line 1068, in _read_ready
    self._protocol.datagram_received(data, addr)
  File "/trader_one/ready_trader_one/messages.py", line 194, in datagram_received
    self.on_datagram(typ, data, HEADER_SIZE, length)
  File "/trader_one/ready_trader_one/base_auto_trader.py", line 63, in on_datagram
    self.on_order_book_update_message(inst, seq, *BOOK_PART.iter_unpack(data[ORDER_BOOK_HEADER_SIZE:]))
  File "/trader_one/autotrader.py", line 100, in on_order_book_update_message
    Lifespan.GOOD_FOR_DAY)
  File "/trader_one/ready_trader_one/base_auto_trader.py", line 150, in send_insert_order
    INSERT_MESSAGE.pack(client_order_id, side, price, volume, lifespan),
struct.error: argument out of range
2021-03-18 13:35:52,184 [WARNING] [TRADER] error with order 121: out-of-order client_order_id in cancel message
2021-03-18 13:35:53,183 [ERROR  ] [asyncio] Exception in callback _SelectorDatagramTransport._read_ready()
handle: <Handle _SelectorDatagramTransport._read_ready()>
Traceback (most recent call last):
  File "/usr/local/lib/python3.6/asyncio/events.py", line 145, in _run
    self._callback(*self._args)
  File "/usr/local/lib/python3.6/asyncio/selector_events.py", line 1068, in _read_ready
    self._protocol.datagram_received(data, addr)
  File "/trader_one/ready_trader_one/messages.py", line 194, in datagram_received
    self.on_datagram(typ, data, HEADER_SIZE, length)
  File "/trader_one/ready_trader_one/base_auto_trader.py", line 63, in on_datagram
    self.on_order_book_update_message(inst, seq, *BOOK_PART.iter_unpack(data[ORDER_BOOK_HEADER_SIZE:]))
  File "/trader_one/autotrader.py", line 100, in on_order_book_update_message
    Lifespan.GOOD_FOR_DAY)
  File "/trader_one/ready_trader_one/base_auto_trader.py", line 150, in send_insert_order
    INSERT_MESSAGE.pack(client_order_id, side, price, volume, lifespan),
struct.error: argument out of range
2021-03-18 13:35:53,185 [WARNING] [TRADER] error with order 120: out-of-order client_order_id in cancel message
2021-03-18 13:35:53,684 [ERROR  ] [asyncio] Exception in callback _SelectorDatagramTransport._read_ready()
handle: <Handle _SelectorDatagramTransport._read_ready()>
Traceback (most recent call last):
  File "/usr/local/lib/python3.6/asyncio/events.py", line 145, in _run
    self._callback(*self._args)
  File "/usr/local/lib/python3.6/asyncio/selector_events.py", line 1068, in _read_ready
    self._protocol.datagram_received(data, addr)
  File "/trader_one/ready_trader_one/messages.py", line 194, in datagram_received
    self.on_datagram(typ, data, HEADER_SIZE, length)
  File "/trader_one/ready_trader_one/base_auto_trader.py", line 63, in on_datagram
    self.on_order_book_update_message(inst, seq, *BOOK_PART.iter_unpack(data[ORDER_BOOK_HEADER_SIZE:]))
  File "/trader_one/autotrader.py", line 92, in on_order_book_update_message
    self.send_insert_order(self.bids[0], Side.BUY, new_bid_price, new_bid_volume, Lifespan.GOOD_FOR_DAY)
  File "/trader_one/ready_trader_one/base_auto_trader.py", line 150, in send_insert_order
    INSERT_MESSAGE.pack(client_order_id, side, price, volume, lifespan),
struct.error: argument out of range
2021-03-18 13:35:53,685 [WARNING] [TRADER] error with order 123: out-of-order client_order_id in cancel message
2021-03-18 13:35:56,934 [ERROR  ] [asyncio] Exception in callback _SelectorDatagramTransport._read_ready()
handle: <Handle _SelectorDatagramTransport._read_ready()>
Traceback (most recent call last):
  File "/usr/local/lib/python3.6/asyncio/events.py", line 145, in _run
    self._callback(*self._args)
  File "/usr/local/lib/python3.6/asyncio/selector_events.py", line 1068, in _read_ready
    self._protocol.datagram_received(data, addr)
  File "/trader_one/ready_trader_one/messages.py", line 194, in datagram_received
    self.on_datagram(typ, data, HEADER_SIZE, length)
  File "/trader_one/ready_trader_one/base_auto_trader.py", line 63, in on_datagram
    self.on_order_book_update_message(inst, seq, *BOOK_PART.iter_unpack(data[ORDER_BOOK_HEADER_SIZE:]))
  File "/trader_one/autotrader.py", line 92, in on_order_book_update_message
    self.send_insert_order(self.bids[0], Side.BUY, new_bid_price, new_bid_volume, Lifespan.GOOD_FOR_DAY)
  File "/trader_one/ready_trader_one/base_auto_trader.py", line 150, in send_insert_order
    INSERT_MESSAGE.pack(client_order_id, side, price, volume, lifespan),
struct.error: argument out of range
2021-03-18 13:35:56,934 [WARNING] [TRADER] error with order 122: out-of-order client_order_id in cancel message
2021-03-18 13:36:00,683 [ERROR  ] [asyncio] Exception in callback _SelectorDatagramTransport._read_ready()
handle: <Handle _SelectorDatagramTransport._read_ready()>
Traceback (most recent call last):
  File "/usr/local/lib/python3.6/asyncio/events.py", line 145, in _run
    self._callback(*self._args)
  File "/usr/local/lib/python3.6/asyncio/selector_events.py", line 1068, in _read_ready
    self._protocol.datagram_received(data, addr)
  File "/trader_one/ready_trader_one/messages.py", line 194, in datagram_received
    self.on_datagram(typ, data, HEADER_SIZE, length)
  File "/trader_one/ready_trader_one/base_auto_trader.py", line 63, in on_datagram
    self.on_order_book_update_message(inst, seq, *BOOK_PART.iter_unpack(data[ORDER_BOOK_HEADER_SIZE:]))
  File "/trader_one/autotrader.py", line 92, in on_order_book_update_message
    self.send_insert_order(self.bids[0], Side.BUY, new_bid_price, new_bid_volume, Lifespan.GOOD_FOR_DAY)
  File "/trader_one/ready_trader_one/base_auto_trader.py", line 150, in send_insert_order
    INSERT_MESSAGE.pack(client_order_id, side, price, volume, lifespan),
struct.error: argument out of range
2021-03-18 13:36:00,684 [WARNING] [TRADER] error with order 124: out-of-order client_order_id in cancel message
2021-03-18 13:36:06,183 [ERROR  ] [asyncio] Exception in callback _SelectorDatagramTransport._read_ready()
handle: <Handle _SelectorDatagramTransport._read_ready()>
Traceback (most recent call last):
  File "/usr/local/lib/python3.6/asyncio/events.py", line 145, in _run
    self._callback(*self._args)
  File "/usr/local/lib/python3.6/asyncio/selector_events.py", line 1068, in _read_ready
    self._protocol.datagram_received(data, addr)
  File "/trader_one/ready_trader_one/messages.py", line 194, in datagram_received
    self.on_datagram(typ, data, HEADER_SIZE, length)
  File "/trader_one/ready_trader_one/base_auto_trader.py", line 63, in on_datagram
    self.on_order_book_update_message(inst, seq, *BOOK_PART.iter_unpack(data[ORDER_BOOK_HEADER_SIZE:]))
  File "/trader_one/autotrader.py", line 100, in on_order_book_update_message
    Lifespan.GOOD_FOR_DAY)
  File "/trader_one/ready_trader_one/base_auto_trader.py", line 150, in send_insert_order
    INSERT_MESSAGE.pack(client_order_id, side, price, volume, lifespan),
struct.error: argument out of range
2021-03-18 13:36:06,185 [WARNING] [TRADER] error with order 126: out-of-order client_order_id in cancel message
2021-03-18 13:36:10,934 [ERROR  ] [asyncio] Exception in callback _SelectorDatagramTransport._read_ready()
handle: <Handle _SelectorDatagramTransport._read_ready()>
Traceback (most recent call last):
  File "/usr/local/lib/python3.6/asyncio/events.py", line 145, in _run
    self._callback(*self._args)
  File "/usr/local/lib/python3.6/asyncio/selector_events.py", line 1068, in _read_ready
    self._protocol.datagram_received(data, addr)
  File "/trader_one/ready_trader_one/messages.py", line 194, in datagram_received
    self.on_datagram(typ, data, HEADER_SIZE, length)
  File "/trader_one/ready_trader_one/base_auto_trader.py", line 63, in on_datagram
    self.on_order_book_update_message(inst, seq, *BOOK_PART.iter_unpack(data[ORDER_BOOK_HEADER_SIZE:]))
  File "/trader_one/autotrader.py", line 92, in on_order_book_update_message
    self.send_insert_order(self.bids[0], Side.BUY, new_bid_price, new_bid_volume, Lifespan.GOOD_FOR_DAY)
  File "/trader_one/ready_trader_one/base_auto_trader.py", line 150, in send_insert_order
    INSERT_MESSAGE.pack(client_order_id, side, price, volume, lifespan),
struct.error: argument out of range
2021-03-18 13:36:10,935 [WARNING] [TRADER] error with order 127: out-of-order client_order_id in cancel message
2021-03-18 13:36:14,183 [ERROR  ] [asyncio] Exception in callback _SelectorDatagramTransport._read_ready()
handle: <Handle _SelectorDatagramTransport._read_ready()>
Traceback (most recent call last):
  File "/usr/local/lib/python3.6/asyncio/events.py", line 145, in _run
    self._callback(*self._args)
  File "/usr/local/lib/python3.6/asyncio/selector_events.py", line 1068, in _read_ready
    self._protocol.datagram_received(data, addr)
  File "/trader_one/ready_trader_one/messages.py", line 194, in datagram_received
    self.on_datagram(typ, data, HEADER_SIZE, length)
  File "/trader_one/ready_trader_one/base_auto_trader.py", line 63, in on_datagram
    self.on_order_book_update_message(inst, seq, *BOOK_PART.iter_unpack(data[ORDER_BOOK_HEADER_SIZE:]))
  File "/trader_one/autotrader.py", line 100, in on_order_book_update_message
    Lifespan.GOOD_FOR_DAY)
  File "/trader_one/ready_trader_one/base_auto_trader.py", line 150, in send_insert_order
    INSERT_MESSAGE.pack(client_order_id, side, price, volume, lifespan),
struct.error: argument out of range
2021-03-18 13:36:14,184 [WARNING] [TRADER] error with order 128: out-of-order client_order_id in cancel message
2021-03-18 13:36:14,934 [ERROR  ] [asyncio] Exception in callback _SelectorDatagramTransport._read_ready()
handle: <Handle _SelectorDatagramTransport._read_ready()>
Traceback (most recent call last):
  File "/usr/local/lib/python3.6/asyncio/events.py", line 145, in _run
    self._callback(*self._args)
  File "/usr/local/lib/python3.6/asyncio/selector_events.py", line 1068, in _read_ready
    self._protocol.datagram_received(data, addr)
  File "/trader_one/ready_trader_one/messages.py", line 194, in datagram_received
    self.on_datagram(typ, data, HEADER_SIZE, length)
  File "/trader_one/ready_trader_one/base_auto_trader.py", line 63, in on_datagram
    self.on_order_book_update_message(inst, seq, *BOOK_PART.iter_unpack(data[ORDER_BOOK_HEADER_SIZE:]))
  File "/trader_one/autotrader.py", line 92, in on_order_book_update_message
    self.send_insert_order(self.bids[0], Side.BUY, new_bid_price, new_bid_volume, Lifespan.GOOD_FOR_DAY)
  File "/trader_one/ready_trader_one/base_auto_trader.py", line 150, in send_insert_order
    INSERT_MESSAGE.pack(client_order_id, side, price, volume, lifespan),
struct.error: argument out of range
2021-03-18 13:36:14,934 [WARNING] [TRADER] error with order 129: out-of-order client_order_id in cancel message
2021-03-18 13:36:15,183 [ERROR  ] [asyncio] Exception in callback _SelectorDatagramTransport._read_ready()
handle: <Handle _SelectorDatagramTransport._read_ready()>
Traceback (most recent call last):
  File "/usr/local/lib/python3.6/asyncio/events.py", line 145, in _run
    self._callback(*self._args)
  File "/usr/local/lib/python3.6/asyncio/selector_events.py", line 1068, in _read_ready
    self._protocol.datagram_received(data, addr)
  File "/trader_one/ready_trader_one/messages.py", line 194, in datagram_received
    self.on_datagram(typ, data, HEADER_SIZE, length)
  File "/trader_one/ready_trader_one/base_auto_trader.py", line 63, in on_datagram
    self.on_order_book_update_message(inst, seq, *BOOK_PART.iter_unpack(data[ORDER_BOOK_HEADER_SIZE:]))
  File "/trader_one/autotrader.py", line 100, in on_order_book_update_message
    Lifespan.GOOD_FOR_DAY)
  File "/trader_one/ready_trader_one/base_auto_trader.py", line 150, in send_insert_order
    INSERT_MESSAGE.pack(client_order_id, side, price, volume, lifespan),
struct.error: argument out of range
2021-03-18 13:36:15,184 [WARNING] [TRADER] error with order 130: out-of-order client_order_id in cancel message
2021-03-18 13:36:15,684 [ERROR  ] [asyncio] Exception in callback _SelectorDatagramTransport._read_ready()
handle: <Handle _SelectorDatagramTransport._read_ready()>
Traceback (most recent call last):
  File "/usr/local/lib/python3.6/asyncio/events.py", line 145, in _run
    self._callback(*self._args)
  File "/usr/local/lib/python3.6/asyncio/selector_events.py", line 1068, in _read_ready
    self._protocol.datagram_received(data, addr)
  File "/trader_one/ready_trader_one/messages.py", line 194, in datagram_received
    self.on_datagram(typ, data, HEADER_SIZE, length)
  File "/trader_one/ready_trader_one/base_auto_trader.py", line 63, in on_datagram
    self.on_order_book_update_message(inst, seq, *BOOK_PART.iter_unpack(data[ORDER_BOOK_HEADER_SIZE:]))
  File "/trader_one/autotrader.py", line 92, in on_order_book_update_message
    self.send_insert_order(self.bids[0], Side.BUY, new_bid_price, new_bid_volume, Lifespan.GOOD_FOR_DAY)
  File "/trader_one/ready_trader_one/base_auto_trader.py", line 150, in send_insert_order
    INSERT_MESSAGE.pack(client_order_id, side, price, volume, lifespan),
struct.error: argument out of range
2021-03-18 13:36:15,684 [WARNING] [TRADER] error with order 131: out-of-order client_order_id in cancel message
2021-03-18 13:36:19,683 [ERROR  ] [asyncio] Exception in callback _SelectorDatagramTransport._read_ready()
handle: <Handle _SelectorDatagramTransport._read_ready()>
Traceback (most recent call last):
  File "/usr/local/lib/python3.6/asyncio/events.py", line 145, in _run
    self._callback(*self._args)
  File "/usr/local/lib/python3.6/asyncio/selector_events.py", line 1068, in _read_ready
    self._protocol.datagram_received(data, addr)
  File "/trader_one/ready_trader_one/messages.py", line 194, in datagram_received
    self.on_datagram(typ, data, HEADER_SIZE, length)
  File "/trader_one/ready_trader_one/base_auto_trader.py", line 63, in on_datagram
    self.on_order_book_update_message(inst, seq, *BOOK_PART.iter_unpack(data[ORDER_BOOK_HEADER_SIZE:]))
  File "/trader_one/autotrader.py", line 92, in on_order_book_update_message
    self.send_insert_order(self.bids[0], Side.BUY, new_bid_price, new_bid_volume, Lifespan.GOOD_FOR_DAY)
  File "/trader_one/ready_trader_one/base_auto_trader.py", line 150, in send_insert_order
    INSERT_MESSAGE.pack(client_order_id, side, price, volume, lifespan),
struct.error: argument out of range
2021-03-18 13:36:19,685 [WARNING] [TRADER] error with order 125: out-of-order client_order_id in cancel message
2021-03-18 13:36:22,183 [ERROR  ] [asyncio] Exception in callback _SelectorDatagramTransport._read_ready()
handle: <Handle _SelectorDatagramTransport._read_ready()>
Traceback (most recent call last):
  File "/usr/local/lib/python3.6/asyncio/events.py", line 145, in _run
    self._callback(*self._args)
  File "/usr/local/lib/python3.6/asyncio/selector_events.py", line 1068, in _read_ready
    self._protocol.datagram_received(data, addr)
  File "/trader_one/ready_trader_one/messages.py", line 194, in datagram_received
    self.on_datagram(typ, data, HEADER_SIZE, length)
  File "/trader_one/ready_trader_one/base_auto_trader.py", line 63, in on_datagram
    self.on_order_book_update_message(inst, seq, *BOOK_PART.iter_unpack(data[ORDER_BOOK_HEADER_SIZE:]))
  File "/trader_one/autotrader.py", line 100, in on_order_book_update_message
    Lifespan.GOOD_FOR_DAY)
  File "/trader_one/ready_trader_one/base_auto_trader.py", line 150, in send_insert_order
    INSERT_MESSAGE.pack(client_order_id, side, price, volume, lifespan),
struct.error: argument out of range
2021-03-18 13:36:22,185 [WARNING] [TRADER] error with order 133: out-of-order client_order_id in cancel message
2021-03-18 13:36:23,433 [ERROR  ] [asyncio] Exception in callback _SelectorDatagramTransport._read_ready()
handle: <Handle _SelectorDatagramTransport._read_ready()>
Traceback (most recent call last):
  File "/usr/local/lib/python3.6/asyncio/events.py", line 145, in _run
    self._callback(*self._args)
  File "/usr/local/lib/python3.6/asyncio/selector_events.py", line 1068, in _read_ready
    self._protocol.datagram_received(data, addr)
  File "/trader_one/ready_trader_one/messages.py", line 194, in datagram_received
    self.on_datagram(typ, data, HEADER_SIZE, length)
  File "/trader_one/ready_trader_one/base_auto_trader.py", line 63, in on_datagram
    self.on_order_book_update_message(inst, seq, *BOOK_PART.iter_unpack(data[ORDER_BOOK_HEADER_SIZE:]))
  File "/trader_one/autotrader.py", line 92, in on_order_book_update_message
    self.send_insert_order(self.bids[0], Side.BUY, new_bid_price, new_bid_volume, Lifespan.GOOD_FOR_DAY)
  File "/trader_one/ready_trader_one/base_auto_trader.py", line 150, in send_insert_order
    INSERT_MESSAGE.pack(client_order_id, side, price, volume, lifespan),
struct.error: argument out of range
2021-03-18 13:36:23,434 [WARNING] [TRADER] error with order 134: out-of-order client_order_id in cancel message
2021-03-18 13:36:23,683 [ERROR  ] [asyncio] Exception in callback _SelectorDatagramTransport._read_ready()
handle: <Handle _SelectorDatagramTransport._read_ready()>
Traceback (most recent call last):
  File "/usr/local/lib/python3.6/asyncio/events.py", line 145, in _run
    self._callback(*self._args)
  File "/usr/local/lib/python3.6/asyncio/selector_events.py", line 1068, in _read_ready
    self._protocol.datagram_received(data, addr)
  File "/trader_one/ready_trader_one/messages.py", line 194, in datagram_received
    self.on_datagram(typ, data, HEADER_SIZE, length)
  File "/trader_one/ready_trader_one/base_auto_trader.py", line 63, in on_datagram
    self.on_order_book_update_message(inst, seq, *BOOK_PART.iter_unpack(data[ORDER_BOOK_HEADER_SIZE:]))
  File "/trader_one/autotrader.py", line 100, in on_order_book_update_message
    Lifespan.GOOD_FOR_DAY)
  File "/trader_one/ready_trader_one/base_auto_trader.py", line 150, in send_insert_order
    INSERT_MESSAGE.pack(client_order_id, side, price, volume, lifespan),
struct.error: argument out of range
2021-03-18 13:36:23,683 [WARNING] [TRADER] error with order 135: out-of-order client_order_id in cancel message
2021-03-18 13:36:29,184 [ERROR  ] [asyncio] Exception in callback _SelectorDatagramTransport._read_ready()
handle: <Handle _SelectorDatagramTransport._read_ready()>
Traceback (most recent call last):
  File "/usr/local/lib/python3.6/asyncio/events.py", line 145, in _run
    self._callback(*self._args)
  File "/usr/local/lib/python3.6/asyncio/selector_events.py", line 1068, in _read_ready
    self._protocol.datagram_received(data, addr)
  File "/trader_one/ready_trader_one/messages.py", line 194, in datagram_received
    self.on_datagram(typ, data, HEADER_SIZE, length)
  File "/trader_one/ready_trader_one/base_auto_trader.py", line 63, in on_datagram
    self.on_order_book_update_message(inst, seq, *BOOK_PART.iter_unpack(data[ORDER_BOOK_HEADER_SIZE:]))
  File "/trader_one/autotrader.py", line 100, in on_order_book_update_message
    Lifespan.GOOD_FOR_DAY)
  File "/trader_one/ready_trader_one/base_auto_trader.py", line 150, in send_insert_order
    INSERT_MESSAGE.pack(client_order_id, side, price, volume, lifespan),
struct.error: argument out of range
2021-03-18 13:36:29,184 [WARNING] [TRADER] error with order 132: out-of-order client_order_id in cancel message
2021-03-18 13:36:30,183 [ERROR  ] [asyncio] Exception in callback _SelectorDatagramTransport._read_ready()
handle: <Handle _SelectorDatagramTransport._read_ready()>
Traceback (most recent call last):
  File "/usr/local/lib/python3.6/asyncio/events.py", line 145, in _run
    self._callback(*self._args)
  File "/usr/local/lib/python3.6/asyncio/selector_events.py", line 1068, in _read_ready
    self._protocol.datagram_received(data, addr)
  File "/trader_one/ready_trader_one/messages.py", line 194, in datagram_received
    self.on_datagram(typ, data, HEADER_SIZE, length)
  File "/trader_one/ready_trader_one/base_auto_trader.py", line 63, in on_datagram
    self.on_order_book_update_message(inst, seq, *BOOK_PART.iter_unpack(data[ORDER_BOOK_HEADER_SIZE:]))
  File "/trader_one/autotrader.py", line 100, in on_order_book_update_message
    Lifespan.GOOD_FOR_DAY)
  File "/trader_one/ready_trader_one/base_auto_trader.py", line 150, in send_insert_order
    INSERT_MESSAGE.pack(client_order_id, side, price, volume, lifespan),
struct.error: argument out of range
2021-03-18 13:36:30,184 [WARNING] [TRADER] error with order 136: out-of-order client_order_id in cancel message
2021-03-18 13:36:31,184 [ERROR  ] [asyncio] Exception in callback _SelectorDatagramTransport._read_ready()
handle: <Handle _SelectorDatagramTransport._read_ready()>
Traceback (most recent call last):
  File "/usr/local/lib/python3.6/asyncio/events.py", line 145, in _run
    self._callback(*self._args)
  File "/usr/local/lib/python3.6/asyncio/selector_events.py", line 1068, in _read_ready
    self._protocol.datagram_received(data, addr)
  File "/trader_one/ready_trader_one/messages.py", line 194, in datagram_received
    self.on_datagram(typ, data, HEADER_SIZE, length)
  File "/trader_one/ready_trader_one/base_auto_trader.py", line 63, in on_datagram
    self.on_order_book_update_message(inst, seq, *BOOK_PART.iter_unpack(data[ORDER_BOOK_HEADER_SIZE:]))
  File "/trader_one/autotrader.py", line 100, in on_order_book_update_message
    Lifespan.GOOD_FOR_DAY)
  File "/trader_one/ready_trader_one/base_auto_trader.py", line 150, in send_insert_order
    INSERT_MESSAGE.pack(client_order_id, side, price, volume, lifespan),
struct.error: argument out of range
2021-03-18 13:36:31,186 [WARNING] [TRADER] error with order 137: out-of-order client_order_id in cancel message
2021-03-18 13:36:31,434 [ERROR  ] [asyncio] Exception in callback _SelectorDatagramTransport._read_ready()
handle: <Handle _SelectorDatagramTransport._read_ready()>
Traceback (most recent call last):
  File "/usr/local/lib/python3.6/asyncio/events.py", line 145, in _run
    self._callback(*self._args)
  File "/usr/local/lib/python3.6/asyncio/selector_events.py", line 1068, in _read_ready
    self._protocol.datagram_received(data, addr)
  File "/trader_one/ready_trader_one/messages.py", line 194, in datagram_received
    self.on_datagram(typ, data, HEADER_SIZE, length)
  File "/trader_one/ready_trader_one/base_auto_trader.py", line 63, in on_datagram
    self.on_order_book_update_message(inst, seq, *BOOK_PART.iter_unpack(data[ORDER_BOOK_HEADER_SIZE:]))
  File "/trader_one/autotrader.py", line 92, in on_order_book_update_message
    self.send_insert_order(self.bids[0], Side.BUY, new_bid_price, new_bid_volume, Lifespan.GOOD_FOR_DAY)
  File "/trader_one/ready_trader_one/base_auto_trader.py", line 150, in send_insert_order
    INSERT_MESSAGE.pack(client_order_id, side, price, volume, lifespan),
struct.error: argument out of range
2021-03-18 13:36:31,434 [WARNING] [TRADER] error with order 139: out-of-order client_order_id in cancel message
2021-03-18 13:36:31,934 [ERROR  ] [asyncio] Exception in callback _SelectorDatagramTransport._read_ready()
handle: <Handle _SelectorDatagramTransport._read_ready()>
Traceback (most recent call last):
  File "/usr/local/lib/python3.6/asyncio/events.py", line 145, in _run
    self._callback(*self._args)
  File "/usr/local/lib/python3.6/asyncio/selector_events.py", line 1068, in _read_ready
    self._protocol.datagram_received(data, addr)
  File "/trader_one/ready_trader_one/messages.py", line 194, in datagram_received
    self.on_datagram(typ, data, HEADER_SIZE, length)
  File "/trader_one/ready_trader_one/base_auto_trader.py", line 63, in on_datagram
    self.on_order_book_update_message(inst, seq, *BOOK_PART.iter_unpack(data[ORDER_BOOK_HEADER_SIZE:]))
  File "/trader_one/autotrader.py", line 100, in on_order_book_update_message
    Lifespan.GOOD_FOR_DAY)
  File "/trader_one/ready_trader_one/base_auto_trader.py", line 150, in send_insert_order
    INSERT_MESSAGE.pack(client_order_id, side, price, volume, lifespan),
struct.error: argument out of range
2021-03-18 13:36:31,934 [WARNING] [TRADER] error with order 140: out-of-order client_order_id in cancel message
2021-03-18 13:36:32,183 [ERROR  ] [asyncio] Exception in callback _SelectorDatagramTransport._read_ready()
handle: <Handle _SelectorDatagramTransport._read_ready()>
Traceback (most recent call last):
  File "/usr/local/lib/python3.6/asyncio/events.py", line 145, in _run
    self._callback(*self._args)
  File "/usr/local/lib/python3.6/asyncio/selector_events.py", line 1068, in _read_ready
    self._protocol.datagram_received(data, addr)
  File "/trader_one/ready_trader_one/messages.py", line 194, in datagram_received
    self.on_datagram(typ, data, HEADER_SIZE, length)
  File "/trader_one/ready_trader_one/base_auto_trader.py", line 63, in on_datagram
    self.on_order_book_update_message(inst, seq, *BOOK_PART.iter_unpack(data[ORDER_BOOK_HEADER_SIZE:]))
  File "/trader_one/autotrader.py", line 92, in on_order_book_update_message
    self.send_insert_order(self.bids[0], Side.BUY, new_bid_price, new_bid_volume, Lifespan.GOOD_FOR_DAY)
  File "/trader_one/ready_trader_one/base_auto_trader.py", line 150, in send_insert_order
    INSERT_MESSAGE.pack(client_order_id, side, price, volume, lifespan),
struct.error: argument out of range
2021-03-18 13:36:32,183 [WARNING] [TRADER] error with order 141: out-of-order client_order_id in cancel message
2021-03-18 13:36:35,183 [ERROR  ] [asyncio] Exception in callback _SelectorDatagramTransport._read_ready()
handle: <Handle _SelectorDatagramTransport._read_ready()>
Traceback (most recent call last):
  File "/usr/local/lib/python3.6/asyncio/events.py", line 145, in _run
    self._callback(*self._args)
  File "/usr/local/lib/python3.6/asyncio/selector_events.py", line 1068, in _read_ready
    self._protocol.datagram_received(data, addr)
  File "/trader_one/ready_trader_one/messages.py", line 194, in datagram_received
    self.on_datagram(typ, data, HEADER_SIZE, length)
  File "/trader_one/ready_trader_one/base_auto_trader.py", line 63, in on_datagram
    self.on_order_book_update_message(inst, seq, *BOOK_PART.iter_unpack(data[ORDER_BOOK_HEADER_SIZE:]))
  File "/trader_one/autotrader.py", line 92, in on_order_book_update_message
    self.send_insert_order(self.bids[0], Side.BUY, new_bid_price, new_bid_volume, Lifespan.GOOD_FOR_DAY)
  File "/trader_one/ready_trader_one/base_auto_trader.py", line 150, in send_insert_order
    INSERT_MESSAGE.pack(client_order_id, side, price, volume, lifespan),
struct.error: argument out of range
2021-03-18 13:36:35,185 [WARNING] [TRADER] error with order 138: out-of-order client_order_id in cancel message
2021-03-18 13:36:36,683 [ERROR  ] [asyncio] Exception in callback _SelectorDatagramTransport._read_ready()
handle: <Handle _SelectorDatagramTransport._read_ready()>
Traceback (most recent call last):
  File "/usr/local/lib/python3.6/asyncio/events.py", line 145, in _run
    self._callback(*self._args)
  File "/usr/local/lib/python3.6/asyncio/selector_events.py", line 1068, in _read_ready
    self._protocol.datagram_received(data, addr)
  File "/trader_one/ready_trader_one/messages.py", line 194, in datagram_received
    self.on_datagram(typ, data, HEADER_SIZE, length)
  File "/trader_one/ready_trader_one/base_auto_trader.py", line 63, in on_datagram
    self.on_order_book_update_message(inst, seq, *BOOK_PART.iter_unpack(data[ORDER_BOOK_HEADER_SIZE:]))
  File "/trader_one/autotrader.py", line 100, in on_order_book_update_message
    Lifespan.GOOD_FOR_DAY)
  File "/trader_one/ready_trader_one/base_auto_trader.py", line 150, in send_insert_order
    INSERT_MESSAGE.pack(client_order_id, side, price, volume, lifespan),
struct.error: argument out of range
2021-03-18 13:36:36,684 [WARNING] [TRADER] error with order 143: out-of-order client_order_id in cancel message
2021-03-18 13:36:39,183 [ERROR  ] [asyncio] Exception in callback _SelectorDatagramTransport._read_ready()
handle: <Handle _SelectorDatagramTransport._read_ready()>
Traceback (most recent call last):
  File "/usr/local/lib/python3.6/asyncio/events.py", line 145, in _run
    self._callback(*self._args)
  File "/usr/local/lib/python3.6/asyncio/selector_events.py", line 1068, in _read_ready
    self._protocol.datagram_received(data, addr)
  File "/trader_one/ready_trader_one/messages.py", line 194, in datagram_received
    self.on_datagram(typ, data, HEADER_SIZE, length)
  File "/trader_one/ready_trader_one/base_auto_trader.py", line 63, in on_datagram
    self.on_order_book_update_message(inst, seq, *BOOK_PART.iter_unpack(data[ORDER_BOOK_HEADER_SIZE:]))
  File "/trader_one/autotrader.py", line 92, in on_order_book_update_message
    self.send_insert_order(self.bids[0], Side.BUY, new_bid_price, new_bid_volume, Lifespan.GOOD_FOR_DAY)
  File "/trader_one/ready_trader_one/base_auto_trader.py", line 150, in send_insert_order
    INSERT_MESSAGE.pack(client_order_id, side, price, volume, lifespan),
struct.error: argument out of range
2021-03-18 13:36:39,185 [WARNING] [TRADER] error with order 144: out-of-order client_order_id in cancel message
2021-03-18 13:36:41,184 [ERROR  ] [asyncio] Exception in callback _SelectorDatagramTransport._read_ready()
handle: <Handle _SelectorDatagramTransport._read_ready()>
Traceback (most recent call last):
  File "/usr/local/lib/python3.6/asyncio/events.py", line 145, in _run
    self._callback(*self._args)
  File "/usr/local/lib/python3.6/asyncio/selector_events.py", line 1068, in _read_ready
    self._protocol.datagram_received(data, addr)
  File "/trader_one/ready_trader_one/messages.py", line 194, in datagram_received
    self.on_datagram(typ, data, HEADER_SIZE, length)
  File "/trader_one/ready_trader_one/base_auto_trader.py", line 63, in on_datagram
    self.on_order_book_update_message(inst, seq, *BOOK_PART.iter_unpack(data[ORDER_BOOK_HEADER_SIZE:]))
  File "/trader_one/autotrader.py", line 92, in on_order_book_update_message
    self.send_insert_order(self.bids[0], Side.BUY, new_bid_price, new_bid_volume, Lifespan.GOOD_FOR_DAY)
  File "/trader_one/ready_trader_one/base_auto_trader.py", line 150, in send_insert_order
    INSERT_MESSAGE.pack(client_order_id, side, price, volume, lifespan),
struct.error: argument out of range
2021-03-18 13:36:41,185 [WARNING] [TRADER] error with order 142: out-of-order client_order_id in cancel message
2021-03-18 13:36:44,933 [ERROR  ] [asyncio] Exception in callback _SelectorDatagramTransport._read_ready()
handle: <Handle _SelectorDatagramTransport._read_ready()>
Traceback (most recent call last):
  File "/usr/local/lib/python3.6/asyncio/events.py", line 145, in _run
    self._callback(*self._args)
  File "/usr/local/lib/python3.6/asyncio/selector_events.py", line 1068, in _read_ready
    self._protocol.datagram_received(data, addr)
  File "/trader_one/ready_trader_one/messages.py", line 194, in datagram_received
    self.on_datagram(typ, data, HEADER_SIZE, length)
  File "/trader_one/ready_trader_one/base_auto_trader.py", line 63, in on_datagram
    self.on_order_book_update_message(inst, seq, *BOOK_PART.iter_unpack(data[ORDER_BOOK_HEADER_SIZE:]))
  File "/trader_one/autotrader.py", line 100, in on_order_book_update_message
    Lifespan.GOOD_FOR_DAY)
  File "/trader_one/ready_trader_one/base_auto_trader.py", line 150, in send_insert_order
    INSERT_MESSAGE.pack(client_order_id, side, price, volume, lifespan),
struct.error: argument out of range
2021-03-18 13:36:44,935 [WARNING] [TRADER] error with order 146: out-of-order client_order_id in cancel message
2021-03-18 13:36:45,683 [ERROR  ] [asyncio] Exception in callback _SelectorDatagramTransport._read_ready()
handle: <Handle _SelectorDatagramTransport._read_ready()>
Traceback (most recent call last):
  File "/usr/local/lib/python3.6/asyncio/events.py", line 145, in _run
    self._callback(*self._args)
  File "/usr/local/lib/python3.6/asyncio/selector_events.py", line 1068, in _read_ready
    self._protocol.datagram_received(data, addr)
  File "/trader_one/ready_trader_one/messages.py", line 194, in datagram_received
    self.on_datagram(typ, data, HEADER_SIZE, length)
  File "/trader_one/ready_trader_one/base_auto_trader.py", line 63, in on_datagram
    self.on_order_book_update_message(inst, seq, *BOOK_PART.iter_unpack(data[ORDER_BOOK_HEADER_SIZE:]))
  File "/trader_one/autotrader.py", line 92, in on_order_book_update_message
    self.send_insert_order(self.bids[0], Side.BUY, new_bid_price, new_bid_volume, Lifespan.GOOD_FOR_DAY)
  File "/trader_one/ready_trader_one/base_auto_trader.py", line 150, in send_insert_order
    INSERT_MESSAGE.pack(client_order_id, side, price, volume, lifespan),
struct.error: argument out of range
2021-03-18 13:36:45,684 [WARNING] [TRADER] error with order 147: out-of-order client_order_id in cancel message
2021-03-18 13:36:46,433 [ERROR  ] [asyncio] Exception in callback _SelectorDatagramTransport._read_ready()
handle: <Handle _SelectorDatagramTransport._read_ready()>
Traceback (most recent call last):
  File "/usr/local/lib/python3.6/asyncio/events.py", line 145, in _run
    self._callback(*self._args)
  File "/usr/local/lib/python3.6/asyncio/selector_events.py", line 1068, in _read_ready
    self._protocol.datagram_received(data, addr)
  File "/trader_one/ready_trader_one/messages.py", line 194, in datagram_received
    self.on_datagram(typ, data, HEADER_SIZE, length)
  File "/trader_one/ready_trader_one/base_auto_trader.py", line 63, in on_datagram
    self.on_order_book_update_message(inst, seq, *BOOK_PART.iter_unpack(data[ORDER_BOOK_HEADER_SIZE:]))
  File "/trader_one/autotrader.py", line 100, in on_order_book_update_message
    Lifespan.GOOD_FOR_DAY)
  File "/trader_one/ready_trader_one/base_auto_trader.py", line 150, in send_insert_order
    INSERT_MESSAGE.pack(client_order_id, side, price, volume, lifespan),
struct.error: argument out of range
2021-03-18 13:36:46,434 [WARNING] [TRADER] error with order 148: out-of-order client_order_id in cancel message
2021-03-18 13:36:51,933 [ERROR  ] [asyncio] Exception in callback _SelectorDatagramTransport._read_ready()
handle: <Handle _SelectorDatagramTransport._read_ready()>
Traceback (most recent call last):
  File "/usr/local/lib/python3.6/asyncio/events.py", line 145, in _run
    self._callback(*self._args)
  File "/usr/local/lib/python3.6/asyncio/selector_events.py", line 1068, in _read_ready
    self._protocol.datagram_received(data, addr)
  File "/trader_one/ready_trader_one/messages.py", line 194, in datagram_received
    self.on_datagram(typ, data, HEADER_SIZE, length)
  File "/trader_one/ready_trader_one/base_auto_trader.py", line 63, in on_datagram
    self.on_order_book_update_message(inst, seq, *BOOK_PART.iter_unpack(data[ORDER_BOOK_HEADER_SIZE:]))
  File "/trader_one/autotrader.py", line 100, in on_order_book_update_message
    Lifespan.GOOD_FOR_DAY)
  File "/trader_one/ready_trader_one/base_auto_trader.py", line 150, in send_insert_order
    INSERT_MESSAGE.pack(client_order_id, side, price, volume, lifespan),
struct.error: argument out of range
2021-03-18 13:36:51,933 [WARNING] [TRADER] error with order 145: out-of-order client_order_id in cancel message
2021-03-18 13:36:57,184 [ERROR  ] [asyncio] Exception in callback _SelectorDatagramTransport._read_ready()
handle: <Handle _SelectorDatagramTransport._read_ready()>
Traceback (most recent call last):
  File "/usr/local/lib/python3.6/asyncio/events.py", line 145, in _run
    self._callback(*self._args)
  File "/usr/local/lib/python3.6/asyncio/selector_events.py", line 1068, in _read_ready
    self._protocol.datagram_received(data, addr)
  File "/trader_one/ready_trader_one/messages.py", line 194, in datagram_received
    self.on_datagram(typ, data, HEADER_SIZE, length)
  File "/trader_one/ready_trader_one/base_auto_trader.py", line 63, in on_datagram
    self.on_order_book_update_message(inst, seq, *BOOK_PART.iter_unpack(data[ORDER_BOOK_HEADER_SIZE:]))
  File "/trader_one/autotrader.py", line 92, in on_order_book_update_message
    self.send_insert_order(self.bids[0], Side.BUY, new_bid_price, new_bid_volume, Lifespan.GOOD_FOR_DAY)
  File "/trader_one/ready_trader_one/base_auto_trader.py", line 150, in send_insert_order
    INSERT_MESSAGE.pack(client_order_id, side, price, volume, lifespan),
struct.error: argument out of range
2021-03-18 13:36:57,185 [WARNING] [TRADER] error with order 150: out-of-order client_order_id in cancel message
2021-03-18 13:36:57,683 [ERROR  ] [asyncio] Exception in callback _SelectorDatagramTransport._read_ready()
handle: <Handle _SelectorDatagramTransport._read_ready()>
Traceback (most recent call last):
  File "/usr/local/lib/python3.6/asyncio/events.py", line 145, in _run
    self._callback(*self._args)
  File "/usr/local/lib/python3.6/asyncio/selector_events.py", line 1068, in _read_ready
    self._protocol.datagram_received(data, addr)
  File "/trader_one/ready_trader_one/messages.py", line 194, in datagram_received
    self.on_datagram(typ, data, HEADER_SIZE, length)
  File "/trader_one/ready_trader_one/base_auto_trader.py", line 63, in on_datagram
    self.on_order_book_update_message(inst, seq, *BOOK_PART.iter_unpack(data[ORDER_BOOK_HEADER_SIZE:]))
  File "/trader_one/autotrader.py", line 100, in on_order_book_update_message
    Lifespan.GOOD_FOR_DAY)
  File "/trader_one/ready_trader_one/base_auto_trader.py", line 150, in send_insert_order
    INSERT_MESSAGE.pack(client_order_id, side, price, volume, lifespan),
struct.error: argument out of range
2021-03-18 13:36:57,684 [WARNING] [TRADER] error with order 151: out-of-order client_order_id in cancel message
2021-03-18 13:36:57,934 [ERROR  ] [asyncio] Exception in callback _SelectorDatagramTransport._read_ready()
handle: <Handle _SelectorDatagramTransport._read_ready()>
Traceback (most recent call last):
  File "/usr/local/lib/python3.6/asyncio/events.py", line 145, in _run
    self._callback(*self._args)
  File "/usr/local/lib/python3.6/asyncio/selector_events.py", line 1068, in _read_ready
    self._protocol.datagram_received(data, addr)
  File "/trader_one/ready_trader_one/messages.py", line 194, in datagram_received
    self.on_datagram(typ, data, HEADER_SIZE, length)
  File "/trader_one/ready_trader_one/base_auto_trader.py", line 63, in on_datagram
    self.on_order_book_update_message(inst, seq, *BOOK_PART.iter_unpack(data[ORDER_BOOK_HEADER_SIZE:]))
  File "/trader_one/autotrader.py", line 92, in on_order_book_update_message
    self.send_insert_order(self.bids[0], Side.BUY, new_bid_price, new_bid_volume, Lifespan.GOOD_FOR_DAY)
  File "/trader_one/ready_trader_one/base_auto_trader.py", line 150, in send_insert_order
    INSERT_MESSAGE.pack(client_order_id, side, price, volume, lifespan),
struct.error: argument out of range
2021-03-18 13:36:57,934 [WARNING] [TRADER] error with order 152: out-of-order client_order_id in cancel message
2021-03-18 13:37:01,183 [ERROR  ] [asyncio] Exception in callback _SelectorDatagramTransport._read_ready()
handle: <Handle _SelectorDatagramTransport._read_ready()>
Traceback (most recent call last):
  File "/usr/local/lib/python3.6/asyncio/events.py", line 145, in _run
    self._callback(*self._args)
  File "/usr/local/lib/python3.6/asyncio/selector_events.py", line 1068, in _read_ready
    self._protocol.datagram_received(data, addr)
  File "/trader_one/ready_trader_one/messages.py", line 194, in datagram_received
    self.on_datagram(typ, data, HEADER_SIZE, length)
  File "/trader_one/ready_trader_one/base_auto_trader.py", line 63, in on_datagram
    self.on_order_book_update_message(inst, seq, *BOOK_PART.iter_unpack(data[ORDER_BOOK_HEADER_SIZE:]))
  File "/trader_one/autotrader.py", line 92, in on_order_book_update_message
    self.send_insert_order(self.bids[0], Side.BUY, new_bid_price, new_bid_volume, Lifespan.GOOD_FOR_DAY)
  File "/trader_one/ready_trader_one/base_auto_trader.py", line 150, in send_insert_order
    INSERT_MESSAGE.pack(client_order_id, side, price, volume, lifespan),
struct.error: argument out of range
2021-03-18 13:37:01,184 [WARNING] [TRADER] error with order 149: out-of-order client_order_id in cancel message
2021-03-18 13:37:02,683 [ERROR  ] [asyncio] Exception in callback _SelectorDatagramTransport._read_ready()
handle: <Handle _SelectorDatagramTransport._read_ready()>
Traceback (most recent call last):
  File "/usr/local/lib/python3.6/asyncio/events.py", line 145, in _run
    self._callback(*self._args)
  File "/usr/local/lib/python3.6/asyncio/selector_events.py", line 1068, in _read_ready
    self._protocol.datagram_received(data, addr)
  File "/trader_one/ready_trader_one/messages.py", line 194, in datagram_received
    self.on_datagram(typ, data, HEADER_SIZE, length)
  File "/trader_one/ready_trader_one/base_auto_trader.py", line 63, in on_datagram
    self.on_order_book_update_message(inst, seq, *BOOK_PART.iter_unpack(data[ORDER_BOOK_HEADER_SIZE:]))
  File "/trader_one/autotrader.py", line 100, in on_order_book_update_message
    Lifespan.GOOD_FOR_DAY)
  File "/trader_one/ready_trader_one/base_auto_trader.py", line 150, in send_insert_order
    INSERT_MESSAGE.pack(client_order_id, side, price, volume, lifespan),
struct.error: argument out of range
2021-03-18 13:37:02,684 [WARNING] [TRADER] error with order 154: out-of-order client_order_id in cancel message
2021-03-18 13:37:03,933 [ERROR  ] [asyncio] Exception in callback _SelectorDatagramTransport._read_ready()
handle: <Handle _SelectorDatagramTransport._read_ready()>
Traceback (most recent call last):
  File "/usr/local/lib/python3.6/asyncio/events.py", line 145, in _run
    self._callback(*self._args)
  File "/usr/local/lib/python3.6/asyncio/selector_events.py", line 1068, in _read_ready
    self._protocol.datagram_received(data, addr)
  File "/trader_one/ready_trader_one/messages.py", line 194, in datagram_received
    self.on_datagram(typ, data, HEADER_SIZE, length)
  File "/trader_one/ready_trader_one/base_auto_trader.py", line 63, in on_datagram
    self.on_order_book_update_message(inst, seq, *BOOK_PART.iter_unpack(data[ORDER_BOOK_HEADER_SIZE:]))
  File "/trader_one/autotrader.py", line 92, in on_order_book_update_message
    self.send_insert_order(self.bids[0], Side.BUY, new_bid_price, new_bid_volume, Lifespan.GOOD_FOR_DAY)
  File "/trader_one/ready_trader_one/base_auto_trader.py", line 150, in send_insert_order
    INSERT_MESSAGE.pack(client_order_id, side, price, volume, lifespan),
struct.error: argument out of range
2021-03-18 13:37:03,934 [WARNING] [TRADER] error with order 155: out-of-order client_order_id in cancel message
2021-03-18 13:37:05,434 [ERROR  ] [asyncio] Exception in callback _SelectorDatagramTransport._read_ready()
handle: <Handle _SelectorDatagramTransport._read_ready()>
Traceback (most recent call last):
  File "/usr/local/lib/python3.6/asyncio/events.py", line 145, in _run
    self._callback(*self._args)
  File "/usr/local/lib/python3.6/asyncio/selector_events.py", line 1068, in _read_ready
    self._protocol.datagram_received(data, addr)
  File "/trader_one/ready_trader_one/messages.py", line 194, in datagram_received
    self.on_datagram(typ, data, HEADER_SIZE, length)
  File "/trader_one/ready_trader_one/base_auto_trader.py", line 63, in on_datagram
    self.on_order_book_update_message(inst, seq, *BOOK_PART.iter_unpack(data[ORDER_BOOK_HEADER_SIZE:]))
  File "/trader_one/autotrader.py", line 100, in on_order_book_update_message
    Lifespan.GOOD_FOR_DAY)
  File "/trader_one/ready_trader_one/base_auto_trader.py", line 150, in send_insert_order
    INSERT_MESSAGE.pack(client_order_id, side, price, volume, lifespan),
struct.error: argument out of range
2021-03-18 13:37:05,434 [WARNING] [TRADER] error with order 156: out-of-order client_order_id in cancel message
2021-03-18 13:37:07,434 [ERROR  ] [asyncio] Exception in callback _SelectorDatagramTransport._read_ready()
handle: <Handle _SelectorDatagramTransport._read_ready()>
Traceback (most recent call last):
  File "/usr/local/lib/python3.6/asyncio/events.py", line 145, in _run
    self._callback(*self._args)
  File "/usr/local/lib/python3.6/asyncio/selector_events.py", line 1068, in _read_ready
    self._protocol.datagram_received(data, addr)
  File "/trader_one/ready_trader_one/messages.py", line 194, in datagram_received
    self.on_datagram(typ, data, HEADER_SIZE, length)
  File "/trader_one/ready_trader_one/base_auto_trader.py", line 63, in on_datagram
    self.on_order_book_update_message(inst, seq, *BOOK_PART.iter_unpack(data[ORDER_BOOK_HEADER_SIZE:]))
  File "/trader_one/autotrader.py", line 92, in on_order_book_update_message
    self.send_insert_order(self.bids[0], Side.BUY, new_bid_price, new_bid_volume, Lifespan.GOOD_FOR_DAY)
  File "/trader_one/ready_trader_one/base_auto_trader.py", line 150, in send_insert_order
    INSERT_MESSAGE.pack(client_order_id, side, price, volume, lifespan),
struct.error: argument out of range
2021-03-18 13:37:07,434 [WARNING] [TRADER] error with order 157: out-of-order client_order_id in cancel message
2021-03-18 13:37:11,185 [WARNING] [TRADER] error with order 158: out-of-order client_order_id in cancel message
2021-03-18 13:37:11,186 [WARNING] [TRADER] error with order 153: out-of-order client_order_id in cancel message
2021-03-18 13:37:11,433 [ERROR  ] [asyncio] Exception in callback _SelectorDatagramTransport._read_ready()
handle: <Handle _SelectorDatagramTransport._read_ready()>
Traceback (most recent call last):
  File "/usr/local/lib/python3.6/asyncio/events.py", line 145, in _run
    self._callback(*self._args)
  File "/usr/local/lib/python3.6/asyncio/selector_events.py", line 1068, in _read_ready
    self._protocol.datagram_received(data, addr)
  File "/trader_one/ready_trader_one/messages.py", line 194, in datagram_received
    self.on_datagram(typ, data, HEADER_SIZE, length)
  File "/trader_one/ready_trader_one/base_auto_trader.py", line 63, in on_datagram
    self.on_order_book_update_message(inst, seq, *BOOK_PART.iter_unpack(data[ORDER_BOOK_HEADER_SIZE:]))
  File "/trader_one/autotrader.py", line 92, in on_order_book_update_message
    self.send_insert_order(self.bids[0], Side.BUY, new_bid_price, new_bid_volume, Lifespan.GOOD_FOR_DAY)
  File "/trader_one/ready_trader_one/base_auto_trader.py", line 150, in send_insert_order
    INSERT_MESSAGE.pack(client_order_id, side, price, volume, lifespan),
struct.error: argument out of range
2021-03-18 13:37:11,683 [ERROR  ] [asyncio] Exception in callback _SelectorDatagramTransport._read_ready()
handle: <Handle _SelectorDatagramTransport._read_ready()>
Traceback (most recent call last):
  File "/usr/local/lib/python3.6/asyncio/events.py", line 145, in _run
    self._callback(*self._args)
  File "/usr/local/lib/python3.6/asyncio/selector_events.py", line 1068, in _read_ready
    self._protocol.datagram_received(data, addr)
  File "/trader_one/ready_trader_one/messages.py", line 194, in datagram_received
    self.on_datagram(typ, data, HEADER_SIZE, length)
  File "/trader_one/ready_trader_one/base_auto_trader.py", line 63, in on_datagram
    self.on_order_book_update_message(inst, seq, *BOOK_PART.iter_unpack(data[ORDER_BOOK_HEADER_SIZE:]))
  File "/trader_one/autotrader.py", line 100, in on_order_book_update_message
    Lifespan.GOOD_FOR_DAY)
  File "/trader_one/ready_trader_one/base_auto_trader.py", line 150, in send_insert_order
    INSERT_MESSAGE.pack(client_order_id, side, price, volume, lifespan),
struct.error: argument out of range
2021-03-18 13:37:12,935 [ERROR  ] [asyncio] Exception in callback _SelectorDatagramTransport._read_ready()
handle: <Handle _SelectorDatagramTransport._read_ready()>
Traceback (most recent call last):
  File "/usr/local/lib/python3.6/asyncio/events.py", line 145, in _run
    self._callback(*self._args)
  File "/usr/local/lib/python3.6/asyncio/selector_events.py", line 1068, in _read_ready
    self._protocol.datagram_received(data, addr)
  File "/trader_one/ready_trader_one/messages.py", line 194, in datagram_received
    self.on_datagram(typ, data, HEADER_SIZE, length)
  File "/trader_one/ready_trader_one/base_auto_trader.py", line 63, in on_datagram
    self.on_order_book_update_message(inst, seq, *BOOK_PART.iter_unpack(data[ORDER_BOOK_HEADER_SIZE:]))
  File "/trader_one/autotrader.py", line 100, in on_order_book_update_message
    Lifespan.GOOD_FOR_DAY)
  File "/trader_one/ready_trader_one/base_auto_trader.py", line 150, in send_insert_order
    INSERT_MESSAGE.pack(client_order_id, side, price, volume, lifespan),
struct.error: argument out of range
2021-03-18 13:37:12,935 [WARNING] [TRADER] error with order 159: out-of-order client_order_id in cancel message
2021-03-18 13:37:17,433 [ERROR  ] [asyncio] Exception in callback _SelectorDatagramTransport._read_ready()
handle: <Handle _SelectorDatagramTransport._read_ready()>
Traceback (most recent call last):
  File "/usr/local/lib/python3.6/asyncio/events.py", line 145, in _run
    self._callback(*self._args)
  File "/usr/local/lib/python3.6/asyncio/selector_events.py", line 1068, in _read_ready
    self._protocol.datagram_received(data, addr)
  File "/trader_one/ready_trader_one/messages.py", line 194, in datagram_received
    self.on_datagram(typ, data, HEADER_SIZE, length)
  File "/trader_one/ready_trader_one/base_auto_trader.py", line 63, in on_datagram
    self.on_order_book_update_message(inst, seq, *BOOK_PART.iter_unpack(data[ORDER_BOOK_HEADER_SIZE:]))
  File "/trader_one/autotrader.py", line 92, in on_order_book_update_message
    self.send_insert_order(self.bids[0], Side.BUY, new_bid_price, new_bid_volume, Lifespan.GOOD_FOR_DAY)
  File "/trader_one/ready_trader_one/base_auto_trader.py", line 150, in send_insert_order
    INSERT_MESSAGE.pack(client_order_id, side, price, volume, lifespan),
struct.error: argument out of range
2021-03-18 13:37:17,435 [WARNING] [TRADER] error with order 161: out-of-order client_order_id in cancel message
2021-03-18 13:37:17,684 [ERROR  ] [asyncio] Exception in callback _SelectorDatagramTransport._read_ready()
handle: <Handle _SelectorDatagramTransport._read_ready()>
Traceback (most recent call last):
  File "/usr/local/lib/python3.6/asyncio/events.py", line 145, in _run
    self._callback(*self._args)
  File "/usr/local/lib/python3.6/asyncio/selector_events.py", line 1068, in _read_ready
    self._protocol.datagram_received(data, addr)
  File "/trader_one/ready_trader_one/messages.py", line 194, in datagram_received
    self.on_datagram(typ, data, HEADER_SIZE, length)
  File "/trader_one/ready_trader_one/base_auto_trader.py", line 63, in on_datagram
    self.on_order_book_update_message(inst, seq, *BOOK_PART.iter_unpack(data[ORDER_BOOK_HEADER_SIZE:]))
  File "/trader_one/autotrader.py", line 100, in on_order_book_update_message
    Lifespan.GOOD_FOR_DAY)
  File "/trader_one/ready_trader_one/base_auto_trader.py", line 150, in send_insert_order
    INSERT_MESSAGE.pack(client_order_id, side, price, volume, lifespan),
struct.error: argument out of range
2021-03-18 13:37:17,685 [WARNING] [TRADER] error with order 162: out-of-order client_order_id in cancel message
2021-03-18 13:37:18,183 [ERROR  ] [asyncio] Exception in callback _SelectorDatagramTransport._read_ready()
handle: <Handle _SelectorDatagramTransport._read_ready()>
Traceback (most recent call last):
  File "/usr/local/lib/python3.6/asyncio/events.py", line 145, in _run
    self._callback(*self._args)
  File "/usr/local/lib/python3.6/asyncio/selector_events.py", line 1068, in _read_ready
    self._protocol.datagram_received(data, addr)
  File "/trader_one/ready_trader_one/messages.py", line 194, in datagram_received
    self.on_datagram(typ, data, HEADER_SIZE, length)
  File "/trader_one/ready_trader_one/base_auto_trader.py", line 63, in on_datagram
    self.on_order_book_update_message(inst, seq, *BOOK_PART.iter_unpack(data[ORDER_BOOK_HEADER_SIZE:]))
  File "/trader_one/autotrader.py", line 92, in on_order_book_update_message
    self.send_insert_order(self.bids[0], Side.BUY, new_bid_price, new_bid_volume, Lifespan.GOOD_FOR_DAY)
  File "/trader_one/ready_trader_one/base_auto_trader.py", line 150, in send_insert_order
    INSERT_MESSAGE.pack(client_order_id, side, price, volume, lifespan),
struct.error: argument out of range
2021-03-18 13:37:18,184 [WARNING] [TRADER] error with order 163: out-of-order client_order_id in cancel message
2021-03-18 13:37:21,934 [ERROR  ] [asyncio] Exception in callback _SelectorDatagramTransport._read_ready()
handle: <Handle _SelectorDatagramTransport._read_ready()>
Traceback (most recent call last):
  File "/usr/local/lib/python3.6/asyncio/events.py", line 145, in _run
    self._callback(*self._args)
  File "/usr/local/lib/python3.6/asyncio/selector_events.py", line 1068, in _read_ready
    self._protocol.datagram_received(data, addr)
  File "/trader_one/ready_trader_one/messages.py", line 194, in datagram_received
    self.on_datagram(typ, data, HEADER_SIZE, length)
  File "/trader_one/ready_trader_one/base_auto_trader.py", line 63, in on_datagram
    self.on_order_book_update_message(inst, seq, *BOOK_PART.iter_unpack(data[ORDER_BOOK_HEADER_SIZE:]))
  File "/trader_one/autotrader.py", line 92, in on_order_book_update_message
    self.send_insert_order(self.bids[0], Side.BUY, new_bid_price, new_bid_volume, Lifespan.GOOD_FOR_DAY)
  File "/trader_one/ready_trader_one/base_auto_trader.py", line 150, in send_insert_order
    INSERT_MESSAGE.pack(client_order_id, side, price, volume, lifespan),
struct.error: argument out of range
2021-03-18 13:37:21,934 [WARNING] [TRADER] error with order 160: out-of-order client_order_id in cancel message
2021-03-18 13:37:23,433 [ERROR  ] [asyncio] Exception in callback _SelectorDatagramTransport._read_ready()
handle: <Handle _SelectorDatagramTransport._read_ready()>
Traceback (most recent call last):
  File "/usr/local/lib/python3.6/asyncio/events.py", line 145, in _run
    self._callback(*self._args)
  File "/usr/local/lib/python3.6/asyncio/selector_events.py", line 1068, in _read_ready
    self._protocol.datagram_received(data, addr)
  File "/trader_one/ready_trader_one/messages.py", line 194, in datagram_received
    self.on_datagram(typ, data, HEADER_SIZE, length)
  File "/trader_one/ready_trader_one/base_auto_trader.py", line 63, in on_datagram
    self.on_order_book_update_message(inst, seq, *BOOK_PART.iter_unpack(data[ORDER_BOOK_HEADER_SIZE:]))
  File "/trader_one/autotrader.py", line 100, in on_order_book_update_message
    Lifespan.GOOD_FOR_DAY)
  File "/trader_one/ready_trader_one/base_auto_trader.py", line 150, in send_insert_order
    INSERT_MESSAGE.pack(client_order_id, side, price, volume, lifespan),
struct.error: argument out of range
2021-03-18 13:37:23,433 [WARNING] [TRADER] error with order 165: out-of-order client_order_id in cancel message
2021-03-18 13:37:27,184 [ERROR  ] [asyncio] Exception in callback _SelectorDatagramTransport._read_ready()
handle: <Handle _SelectorDatagramTransport._read_ready()>
Traceback (most recent call last):
  File "/usr/local/lib/python3.6/asyncio/events.py", line 145, in _run
    self._callback(*self._args)
  File "/usr/local/lib/python3.6/asyncio/selector_events.py", line 1068, in _read_ready
    self._protocol.datagram_received(data, addr)
  File "/trader_one/ready_trader_one/messages.py", line 194, in datagram_received
    self.on_datagram(typ, data, HEADER_SIZE, length)
  File "/trader_one/ready_trader_one/base_auto_trader.py", line 63, in on_datagram
    self.on_order_book_update_message(inst, seq, *BOOK_PART.iter_unpack(data[ORDER_BOOK_HEADER_SIZE:]))
  File "/trader_one/autotrader.py", line 92, in on_order_book_update_message
    self.send_insert_order(self.bids[0], Side.BUY, new_bid_price, new_bid_volume, Lifespan.GOOD_FOR_DAY)
  File "/trader_one/ready_trader_one/base_auto_trader.py", line 150, in send_insert_order
    INSERT_MESSAGE.pack(client_order_id, side, price, volume, lifespan),
struct.error: argument out of range
2021-03-18 13:37:27,185 [WARNING] [TRADER] error with order 166: out-of-order client_order_id in cancel message
2021-03-18 13:37:27,683 [ERROR  ] [asyncio] Exception in callback _SelectorDatagramTransport._read_ready()
handle: <Handle _SelectorDatagramTransport._read_ready()>
Traceback (most recent call last):
  File "/usr/local/lib/python3.6/asyncio/events.py", line 145, in _run
    self._callback(*self._args)
  File "/usr/local/lib/python3.6/asyncio/selector_events.py", line 1068, in _read_ready
    self._protocol.datagram_received(data, addr)
  File "/trader_one/ready_trader_one/messages.py", line 194, in datagram_received
    self.on_datagram(typ, data, HEADER_SIZE, length)
  File "/trader_one/ready_trader_one/base_auto_trader.py", line 63, in on_datagram
    self.on_order_book_update_message(inst, seq, *BOOK_PART.iter_unpack(data[ORDER_BOOK_HEADER_SIZE:]))
  File "/trader_one/autotrader.py", line 92, in on_order_book_update_message
    self.send_insert_order(self.bids[0], Side.BUY, new_bid_price, new_bid_volume, Lifespan.GOOD_FOR_DAY)
  File "/trader_one/ready_trader_one/base_auto_trader.py", line 150, in send_insert_order
    INSERT_MESSAGE.pack(client_order_id, side, price, volume, lifespan),
struct.error: argument out of range
2021-03-18 13:37:27,685 [WARNING] [TRADER] error with order 164: out-of-order client_order_id in cancel message
2021-03-18 13:37:28,685 [INFO   ] [CONNECTION] fd=8 connection lost
2021-03-18 13:37:28,685 [INFO   ] [APP] closing event loop
